<?xml version="1.0" ?>
<sdf version="1.5">
  <model name="cable">

    <pose>-0.65 -0.3 0.5 0 0 0</pose>


    <link name="plug">
      <pose>0.000000 0.000000 0.000000 0.000000 1.570796 0.000000</pose>
      <inertial>
        <pose>0.000000 0.000000 0.000000 0.000000 0.000000 0.000000</pose>
        <mass>0.100000</mass>
        <inertia>
          <ixx>0.010000</ixx>
          <ixy>0.000000</ixy>
          <ixz>0.000000</ixz>
          <iyy>0.010000</iyy>
          <iyz>0.000000</iyz>
          <izz>0.010000</izz>
        </inertia>
      </inertial>
      <collision name="plug_collision">
        <pose>-0.000000 0.000000 0.000000 0.000000 0.000000 0.000000</pose>
        <geometry>
          <cylinder>
            <radius>0.02</radius>
            <length>0.1</length>
          </cylinder>
        </geometry>
      </collision>
      <visual name="plug_vis">
        <pose>-0.000000 0.000000 0.000000 0.000000 0.000000 0.000000</pose>
        <geometry>
          <cylinder>
            <radius>0.02</radius>
            <length>0.1</length>
          </cylinder>
        </geometry>
      </visual>
      <velocity_decay />
    </link>

    <link name="link_01">
     
      <pose>0.050000 0.000000 0.000000 0.000000 -0.000000 0.000000</pose>
      <inertial>
        <pose>0.000000 0.000000 0.000000 0.000000 -0.000000 0.000000</pose>
        <mass>0.100000</mass>
        <inertia>
          <ixx>0.010000</ixx>
          <ixy>0.000000</ixy>
          <ixz>0.000000</ixz>
          <iyy>0.010000</iyy>
          <iyz>0.000000</iyz>
          <izz>0.010000</izz>
        </inertia>
      </inertial>
      <collision name="link_01_collision">
        <pose>0.025000 0.000000 0.000000 0.000000 1.570790 0.000000</pose>
        <geometry>
          <cylinder>
            <length>0.050000</length>
            <radius>0.007500</radius>
          </cylinder>
        </geometry>
      </collision>
      <visual name="link_01_vis">
        <pose>0.025000 0.000000 0.000000 0.000000 1.570790 0.000000</pose>
        <geometry>
          <cylinder>
            <length>0.050000</length>
            <radius>0.007500</radius>
          </cylinder>
        </geometry>
      </visual>
      <velocity_decay />
    </link>
    <joint name="joint_plug" type="fixed">
      <child>link_01</child>
      <parent>plug</parent>
      <axis>
        <xyz>0.000000 1.000000 0.000000</xyz>
        <limit>
          <lower>-0.200000</lower>
          <upper>0.200000</upper>
        </limit>
        <dynamics>
          <damping>10.000000</damping>
          <friction>0.000000</friction>
        </dynamics>
        <use_parent_model_frame>true</use_parent_model_frame>
      </axis>
    </joint>
    <link name="sphere_02">
      <gravity>false</gravity>
      <pose>0.100000 0.000000 0.000000 0.000000 -0.000000 0.000000</pose>
      <inertial>
        <pose>0.000000 0.000000 0.000000 0.000000 -0.000000 0.000000</pose>
        <mass>0.100000</mass>
        <inertia>
          <ixx>0.010000</ixx>
          <ixy>0.000000</ixy>
          <ixz>0.000000</ixz>
          <iyy>0.010000</iyy>
          <iyz>0.000000</iyz>
          <izz>0.010000</izz>
        </inertia>
      </inertial>
      <collision name="sphere_02_collision">
        <pose>0.000000 0.000000 0.000000 0.000000 -0.000000 0.000000</pose>
        <geometry>
          <sphere>
            <radius>0.007500</radius>
          </sphere>
        </geometry>
      </collision>
      <visual name="sphere_02_vis">
        <pose>0.000000 0.000000 0.000000 0.000000 -0.000000 0.000000</pose>
        <geometry>
          <sphere>
            <radius>0.007500</radius>
          </sphere>
        </geometry>
      </visual>
      <velocity_decay />
    </link>
    <joint name="joint_02_1" type="revolute">
      <child>sphere_02</child>
      <parent>link_01</parent>
      <axis>
        <xyz>0.000000 0.000000 1.000000</xyz>
        <limit>
          <lower>-0.005000</lower>
          <upper>0.005000</upper>
        </limit>
        <dynamics>
          <damping>10.000000</damping>
          <friction>0.000000</friction>
        </dynamics>
        <use_parent_model_frame>true</use_parent_model_frame>
      </axis>
    </joint>
    <link name="link_02">

      <pose>0.100000 0.000000 0.000000 0.000000 -0.000000 0.000000</pose>
      <inertial>
        <pose>0.000000 0.000000 0.000000 0.000000 -0.000000 0.000000</pose>
        <mass>0.100000</mass>
        <inertia>
          <ixx>0.010000</ixx>
          <ixy>0.000000</ixy>
          <ixz>0.000000</ixz>
          <iyy>0.010000</iyy>
          <iyz>0.000000</iyz>
          <izz>0.010000</izz>
        </inertia>
      </inertial>
      <collision name="link_02_collision">
        <pose>0.025000 0.000000 0.000000 0.000000 1.570790 0.000000</pose>
        <geometry>
          <cylinder>
            <length>0.050000</length>
            <radius>0.007500</radius>
          </cylinder>
        </geometry>
      </collision>
      <visual name="link_02_vis">
        <pose>0.025000 0.000000 0.000000 0.000000 1.570790 0.000000</pose>
        <geometry>
          <cylinder>
            <length>0.050000</length>
            <radius>0.007500</radius>
          </cylinder>
        </geometry>
      </visual>
      <velocity_decay />
    </link>
    <joint name="joint_02_2" type="revolute">
      <child>link_02</child>
      <parent>sphere_02</parent>
      <axis>
        <xyz>0.000000 1.000000 0.000000</xyz>
        <dynamics>
          <damping>1.75954</damping>
          <friction>0.000000</friction>
	  <spring_stiffness>0.557738</spring_stiffness>
        </dynamics>
        <use_parent_model_frame>true</use_parent_model_frame>
      </axis>
    </joint>
    <link name="sphere_03">
      <gravity>false</gravity>
      <pose>0.150000 0.000000 0.000000 0.000000 -0.000000 0.000000</pose>
      <inertial>
        <pose>0.000000 0.000000 0.000000 0.000000 -0.000000 0.000000</pose>
        <mass>0.100000</mass>
        <inertia>
          <ixx>0.010000</ixx>
          <ixy>0.000000</ixy>
          <ixz>0.000000</ixz>
          <iyy>0.010000</iyy>
          <iyz>0.000000</iyz>
          <izz>0.010000</izz>
        </inertia>
      </inertial>
      <collision name="sphere_03_collision">
        <pose>0.000000 0.000000 0.000000 0.000000 -0.000000 0.000000</pose>
        <geometry>
          <sphere>
            <radius>0.007500</radius>
          </sphere>
        </geometry>
      </collision>
      <visual name="sphere_03_vis">
        <pose>0.000000 0.000000 0.000000 0.000000 -0.000000 0.000000</pose>
        <geometry>
          <sphere>
            <radius>0.007500</radius>
          </sphere>
        </geometry>
      </visual>
      <velocity_decay />
    </link>
    <joint name="joint_03_1" type="revolute">
      <child>sphere_03</child>
      <parent>link_02</parent>
      <axis>
        <xyz>0.000000 0.000000 1.000000</xyz>
        <limit>
          <lower>-0.005000</lower>
          <upper>0.005000</upper>
        </limit>
        <dynamics>
          <damping>10.000000</damping>
          <friction>0.000000</friction>
        </dynamics>
        <use_parent_model_frame>true</use_parent_model_frame>
      </axis>
    </joint>
    <link name="link_03">
   
      <pose>0.150000 0.000000 0.000000 0.000000 -0.000000 0.000000</pose>
      <inertial>
        <pose>0.000000 0.000000 0.000000 0.000000 -0.000000 0.000000</pose>
        <mass>0.100000</mass>
        <inertia>
          <ixx>0.010000</ixx>
          <ixy>0.000000</ixy>
          <ixz>0.000000</ixz>
          <iyy>0.010000</iyy>
          <iyz>0.000000</iyz>
          <izz>0.010000</izz>
        </inertia>
      </inertial>
      <collision name="link_03_collision">
        <pose>0.025000 0.000000 0.000000 0.000000 1.570790 0.000000</pose>
        <geometry>
          <cylinder>
            <length>0.050000</length>
            <radius>0.007500</radius>
          </cylinder>
        </geometry>
      </collision>
      <visual name="link_03_vis">
        <pose>0.025000 0.000000 0.000000 0.000000 1.570790 0.000000</pose>
        <geometry>
          <cylinder>
            <length>0.050000</length>
            <radius>0.007500</radius>
          </cylinder>
        </geometry>
      </visual>
      <velocity_decay />
    </link>
    <joint name="joint_03_2" type="revolute">
      <child>link_03</child>
      <parent>sphere_03</parent>
      <axis>
        <xyz>0.000000 1.000000 0.000000</xyz>
        <dynamics>
          <damping>3.5445</damping>
          <friction>0.000000</friction>
	  <spring_stiffness>0.906265</spring_stiffness>
        </dynamics>
        <use_parent_model_frame>true</use_parent_model_frame>
      </axis>
    </joint>
    <link name="sphere_04">
      <gravity>false</gravity>
      <pose>0.200000 0.000000 0.000000 0.000000 -0.000000 0.000000</pose>
      <inertial>
        <pose>0.000000 0.000000 0.000000 0.000000 -0.000000 0.000000</pose>
        <mass>0.100000</mass>
        <inertia>
          <ixx>0.010000</ixx>
          <ixy>0.000000</ixy>
          <ixz>0.000000</ixz>
          <iyy>0.010000</iyy>
          <iyz>0.000000</iyz>
          <izz>0.010000</izz>
        </inertia>
      </inertial>
      <collision name="sphere_04_collision">
        <pose>0.000000 0.000000 0.000000 0.000000 -0.000000 0.000000</pose>
        <geometry>
          <sphere>
            <radius>0.007500</radius>
          </sphere>
        </geometry>
      </collision>
      <visual name="sphere_04_vis">
        <pose>0.000000 0.000000 0.000000 0.000000 -0.000000 0.000000</pose>
        <geometry>
          <sphere>
            <radius>0.007500</radius>
          </sphere>
        </geometry>
      </visual>
      <velocity_decay />
    </link>
    <joint name="joint_04_1" type="revolute">
      <child>sphere_04</child>
      <parent>link_03</parent>
      <axis>
        <xyz>0.000000 0.000000 1.000000</xyz>
        <limit>
          <lower>-0.005000</lower>
          <upper>0.005000</upper>
        </limit>
        <dynamics>
          <damping>10.000000</damping>
          <friction>0.000000</friction>
        </dynamics>
        <use_parent_model_frame>true</use_parent_model_frame>
      </axis>
    </joint>
    <link name="link_04">

      <pose>0.200000 0.000000 0.000000 0.000000 -0.000000 0.000000</pose>
      <inertial>
        <pose>0.000000 0.000000 0.000000 0.000000 -0.000000 0.000000</pose>
        <mass>0.0100000</mass>
        <inertia>
          <ixx>0.010000</ixx>
          <ixy>0.000000</ixy>
          <ixz>0.000000</ixz>
          <iyy>0.010000</iyy>
          <iyz>0.000000</iyz>
          <izz>0.010000</izz>
        </inertia>
      </inertial>
      <collision name="link_04_collision">
        <pose>0.025000 0.000000 0.000000 0.000000 1.570790 0.000000</pose>
        <geometry>
          <cylinder>
            <length>0.050000</length>
            <radius>0.007500</radius>
          </cylinder>
        </geometry>
      </collision>
      <visual name="link_04_vis">
        <pose>0.025000 0.000000 0.000000 0.000000 1.570790 0.000000</pose>
        <geometry>
          <cylinder>
            <length>0.050000</length>
            <radius>0.007500</radius>
          </cylinder>
        </geometry>
      </visual>
      <velocity_decay />
    </link>
    <joint name="joint_04_2" type="revolute">
      <child>link_04</child>
      <parent>sphere_04</parent>
      <axis>
        <xyz>0.000000 1.000000 0.000000</xyz>
        <dynamics>
          <damping>6.31788</damping>
          <friction>0.000000</friction>
          <spring_stiffness>0.675703</spring_stiffness>
        </dynamics>
        <use_parent_model_frame>true</use_parent_model_frame>
      </axis>
    </joint>
    <link name="sphere_05">
      <gravity>false</gravity>
      <pose>0.250000 0.000000 0.000000 0.000000 -0.000000 0.000000</pose>
      <inertial>
        <pose>0.000000 0.000000 0.000000 0.000000 -0.000000 0.000000</pose>
        <mass>0.100000</mass>
        <inertia>
          <ixx>0.010000</ixx>
          <ixy>0.000000</ixy>
          <ixz>0.000000</ixz>
          <iyy>0.010000</iyy>
          <iyz>0.000000</iyz>
          <izz>0.010000</izz>
        </inertia>
      </inertial>
      <collision name="sphere_05_collision">
        <pose>0.000000 0.000000 0.000000 0.000000 -0.000000 0.000000</pose>
        <geometry>
          <sphere>
            <radius>0.007500</radius>
          </sphere>
        </geometry>
      </collision>
      <visual name="sphere_05_vis">
        <pose>0.000000 0.000000 0.000000 0.000000 -0.000000 0.000000</pose>
        <geometry>
          <sphere>
            <radius>0.007500</radius>
          </sphere>
        </geometry>
      </visual>
      <velocity_decay />
    </link>
    <joint name="joint_05_1" type="revolute">
      <child>sphere_05</child>
      <parent>link_04</parent>
      <axis>
        <xyz>0.000000 0.000000 1.000000</xyz>
        <limit>
          <lower>-0.005000</lower>
          <upper>0.005000</upper>
        </limit>
        <dynamics>
          <damping>10.000000</damping>
          <friction>0.000000</friction>
        </dynamics>
        <use_parent_model_frame>true</use_parent_model_frame>
      </axis>
    </joint>
    <link name="link_05">
      
      <pose>0.250000 0.000000 0.000000 0.000000 -0.000000 0.000000</pose>
      <inertial>
        <pose>0.000000 0.000000 0.000000 0.000000 -0.000000 0.000000</pose>
        <mass>0.0100000</mass>
        <inertia>
          <ixx>0.010000</ixx>
          <ixy>0.000000</ixy>
          <ixz>0.000000</ixz>
          <iyy>0.010000</iyy>
          <iyz>0.000000</iyz>
          <izz>0.010000</izz>
        </inertia>
      </inertial>
      <collision name="link_05_collision">
        <pose>0.025000 0.000000 0.000000 0.000000 1.570790 0.000000</pose>
        <geometry>
          <cylinder>
            <length>0.050000</length>
            <radius>0.007500</radius>
          </cylinder>
        </geometry>
      </collision>
      <visual name="link_05_vis">
        <pose>0.025000 0.000000 0.000000 0.000000 1.570790 0.000000</pose>
        <geometry>
          <cylinder>
            <length>0.050000</length>
            <radius>0.007500</radius>
          </cylinder>
        </geometry>
      </visual>
      <velocity_decay />
    </link>
    <joint name="joint_05_2" type="revolute">
      <child>link_05</child>
      <parent>sphere_05</parent>
      <axis>
        <xyz>0.000000 1.000000 0.000000</xyz>
        <dynamics>
          <damping>7.02696</damping>
          <friction>0.000000</friction>
          <spring_stiffness>0.710039</spring_stiffness>
        </dynamics>
        <use_parent_model_frame>true</use_parent_model_frame>
      </axis>
    </joint>
    <link name="sphere_06">
      <gravity>false</gravity>
      <pose>0.300000 0.000000 0.000000 0.000000 -0.000000 0.000000</pose>
      <inertial>
        <pose>0.000000 0.000000 0.000000 0.000000 -0.000000 0.000000</pose>
        <mass>0.100000</mass>
        <inertia>
          <ixx>0.010000</ixx>
          <ixy>0.000000</ixy>
          <ixz>0.000000</ixz>
          <iyy>0.010000</iyy>
          <iyz>0.000000</iyz>
          <izz>0.010000</izz>
        </inertia>
      </inertial>
      <collision name="sphere_06_collision">
        <pose>0.000000 0.000000 0.000000 0.000000 -0.000000 0.000000</pose>
        <geometry>
          <sphere>
            <radius>0.007500</radius>
          </sphere>
        </geometry>
      </collision>
      <visual name="sphere_06_vis">
        <pose>0.000000 0.000000 0.000000 0.000000 -0.000000 0.000000</pose>
        <geometry>
          <sphere>
            <radius>0.007500</radius>
          </sphere>
        </geometry>
      </visual>
      <velocity_decay />
    </link>
    <joint name="joint_06_1" type="revolute">
      <child>sphere_06</child>
      <parent>link_05</parent>
      <axis>
        <xyz>0.000000 0.000000 1.000000</xyz>
        <limit>
          <lower>-0.005000</lower>
          <upper>0.005000</upper>
        </limit>
        <dynamics>
          <damping>10.000000</damping>
          <friction>0.000000</friction>
        </dynamics>
        <use_parent_model_frame>true</use_parent_model_frame>
      </axis>
    </joint>
    <link name="link_06">

      <pose>0.300000 0.000000 0.000000 0.000000 -0.000000 0.000000</pose>
      <inertial>
        <pose>0.000000 0.000000 0.000000 0.000000 -0.000000 0.000000</pose>
        <mass>0.0100000</mass>
        <inertia>
          <ixx>0.010000</ixx>
          <ixy>0.000000</ixy>
          <ixz>0.000000</ixz>
          <iyy>0.010000</iyy>
          <iyz>0.000000</iyz>
          <izz>0.010000</izz>
        </inertia>
      </inertial>
      <collision name="link_06_collision">
        <pose>0.025000 0.000000 0.000000 0.000000 1.570790 0.000000</pose>
        <geometry>
          <cylinder>
            <length>0.050000</length>
            <radius>0.007500</radius>
          </cylinder>
        </geometry>
      </collision>
      <visual name="link_06_vis">
        <pose>0.025000 0.000000 0.000000 0.000000 1.570790 0.000000</pose>
        <geometry>
          <cylinder>
            <length>0.050000</length>
            <radius>0.007500</radius>
          </cylinder>
        </geometry>
      </visual>
      <velocity_decay />
    </link>
    <joint name="joint_06_2" type="revolute">
      <child>link_06</child>
      <parent>sphere_06</parent>
      <axis>
        <xyz>0.000000 1.000000 0.000000</xyz>
        <limit>
          <lower>-0.500000</lower>
          <upper>0.500000</upper>
        </limit>
        <dynamics>
          <damping>10.000000</damping>
          <friction>0.000000</friction>
        </dynamics>
        <use_parent_model_frame>true</use_parent_model_frame>
      </axis>
    </joint>
    <link name="sphere_07">
      <gravity>false</gravity>
      <pose>0.350000 0.000000 0.000000 0.000000 -0.000000 0.000000</pose>
      <inertial>
        <pose>0.000000 0.000000 0.000000 0.000000 -0.000000 0.000000</pose>
        <mass>0.100000</mass>
        <inertia>
          <ixx>0.010000</ixx>
          <ixy>0.000000</ixy>
          <ixz>0.000000</ixz>
          <iyy>0.010000</iyy>
          <iyz>0.000000</iyz>
          <izz>0.010000</izz>
        </inertia>
      </inertial>
      <collision name="sphere_07_collision">
        <pose>0.000000 0.000000 0.000000 0.000000 -0.000000 0.000000</pose>
        <geometry>
          <sphere>
            <radius>0.007500</radius>
          </sphere>
        </geometry>
      </collision>
      <visual name="sphere_07_vis">
        <pose>0.000000 0.000000 0.000000 0.000000 -0.000000 0.000000</pose>
        <geometry>
          <sphere>
            <radius>0.007500</radius>
          </sphere>
        </geometry>
      </visual>
      <velocity_decay />
    </link>
    <joint name="joint_07_1" type="revolute">
      <child>sphere_07</child>
      <parent>link_06</parent>
      <axis>
        <xyz>0.000000 0.000000 1.000000</xyz>
        <limit>
          <lower>-0.005000</lower>
          <upper>0.005000</upper>
        </limit>
        <dynamics>
          <damping>10.000000</damping>
          <friction>0.000000</friction>
        </dynamics>
        <use_parent_model_frame>true</use_parent_model_frame>
      </axis>
    </joint>
    <link name="link_07">

      <pose>0.350000 0.000000 0.000000 0.000000 -0.000000 0.000000</pose>
      <inertial>
        <pose>0.000000 0.000000 0.000000 0.000000 -0.000000 0.000000</pose>
        <mass>0.0100000</mass>
        <inertia>
          <ixx>0.010000</ixx>
          <ixy>0.000000</ixy>
          <ixz>0.000000</ixz>
          <iyy>0.010000</iyy>
          <iyz>0.000000</iyz>
          <izz>0.010000</izz>
        </inertia>
      </inertial>
      <collision name="link_07_collision">
        <pose>0.025000 0.000000 0.000000 0.000000 1.570790 0.000000</pose>
        <geometry>
          <cylinder>
            <length>0.050000</length>
            <radius>0.007500</radius>
          </cylinder>
        </geometry>
      </collision>
      <visual name="link_07_vis">
        <pose>0.025000 0.000000 0.000000 0.000000 1.570790 0.000000</pose>
        <geometry>
          <cylinder>
            <length>0.050000</length>
            <radius>0.007500</radius>
          </cylinder>
        </geometry>
      </visual>
      <velocity_decay />
    </link>
    <joint name="joint_07_2" type="revolute">
      <child>link_07</child>
      <parent>sphere_07</parent>
      <axis>
        <xyz>0.000000 1.000000 0.000000</xyz>
        <limit>
          <lower>-0.500000</lower>
          <upper>0.500000</upper>
        </limit>
        <dynamics>
          <damping>10.000000</damping>
          <friction>0.000000</friction>
        </dynamics>
        <use_parent_model_frame>true</use_parent_model_frame>
      </axis>
    </joint>
    <link name="sphere_08">
      <gravity>false</gravity>
      <pose>0.400000 0.000000 0.000000 0.000000 -0.000000 0.000000</pose>
      <inertial>
        <pose>0.000000 0.000000 0.000000 0.000000 -0.000000 0.000000</pose>
        <mass>0.100000</mass>
        <inertia>
          <ixx>0.010000</ixx>
          <ixy>0.000000</ixy>
          <ixz>0.000000</ixz>
          <iyy>0.010000</iyy>
          <iyz>0.000000</iyz>
          <izz>0.010000</izz>
        </inertia>
      </inertial>
      <collision name="sphere_08_collision">
        <pose>0.000000 0.000000 0.000000 0.000000 -0.000000 0.000000</pose>
        <geometry>
          <sphere>
            <radius>0.007500</radius>
          </sphere>
        </geometry>
      </collision>
      <visual name="sphere_08_vis">
        <pose>0.000000 0.000000 0.000000 0.000000 -0.000000 0.000000</pose>
        <geometry>
          <sphere>
            <radius>0.007500</radius>
          </sphere>
        </geometry>
      </visual>
      <velocity_decay />
    </link>
    <joint name="joint_08_1" type="revolute">
      <child>sphere_08</child>
      <parent>link_07</parent>
      <axis>
        <xyz>0.000000 0.000000 1.000000</xyz>
        <limit>
          <lower>-0.005000</lower>
          <upper>0.005000</upper>
        </limit>
        <dynamics>
          <damping>10.000000</damping>
          <friction>0.000000</friction>
        </dynamics>
        <use_parent_model_frame>true</use_parent_model_frame>
      </axis>
    </joint>
    <link name="link_08">

      <pose>0.400000 0.000000 0.000000 0.000000 -0.000000 0.000000</pose>
      <inertial>
        <pose>0.000000 0.000000 0.000000 0.000000 -0.000000 0.000000</pose>
        <mass>0.0100000</mass>
        <inertia>
          <ixx>0.010000</ixx>
          <ixy>0.000000</ixy>
          <ixz>0.000000</ixz>
          <iyy>0.010000</iyy>
          <iyz>0.000000</iyz>
          <izz>0.010000</izz>
        </inertia>
      </inertial>
      <collision name="link_08_collision">
        <pose>0.025000 0.000000 0.000000 0.000000 1.570790 0.000000</pose>
        <geometry>
          <cylinder>
            <length>0.050000</length>
            <radius>0.007500</radius>
          </cylinder>
        </geometry>
      </collision>
      <visual name="link_08_vis">
        <pose>0.025000 0.000000 0.000000 0.000000 1.570790 0.000000</pose>
        <geometry>
          <cylinder>
            <length>0.050000</length>
            <radius>0.007500</radius>
          </cylinder>
        </geometry>
      </visual>
      <velocity_decay />
    </link>
    <joint name="joint_08_2" type="revolute">
      <child>link_08</child>
      <parent>sphere_08</parent>
      <axis>
        <xyz>0.000000 1.000000 0.000000</xyz>
        <limit>
          <lower>-0.500000</lower>
          <upper>0.500000</upper>
        </limit>
        <dynamics>
          <damping>10.000000</damping>
          <friction>0.000000</friction>
        </dynamics>
        <use_parent_model_frame>true</use_parent_model_frame>
      </axis>
    </joint>
    <link name="sphere_09">
      <gravity>false</gravity>
      <pose>0.450000 0.000000 0.000000 0.000000 -0.000000 0.000000</pose>
      <inertial>
        <pose>0.000000 0.000000 0.000000 0.000000 -0.000000 0.000000</pose>
        <mass>0.100000</mass>
        <inertia>
          <ixx>0.010000</ixx>
          <ixy>0.000000</ixy>
          <ixz>0.000000</ixz>
          <iyy>0.010000</iyy>
          <iyz>0.000000</iyz>
          <izz>0.010000</izz>
        </inertia>
      </inertial>
      <collision name="sphere_09_collision">
        <pose>0.000000 0.000000 0.000000 0.000000 -0.000000 0.000000</pose>
        <geometry>
          <sphere>
            <radius>0.007500</radius>
          </sphere>
        </geometry>
      </collision>
      <visual name="sphere_09_vis">
        <pose>0.000000 0.000000 0.000000 0.000000 -0.000000 0.000000</pose>
        <geometry>
          <sphere>
            <radius>0.007500</radius>
          </sphere>
        </geometry>
      </visual>
      <velocity_decay />
    </link>
    <joint name="joint_09_1" type="revolute">
      <child>sphere_09</child>
      <parent>link_08</parent>
      <axis>
        <xyz>0.000000 0.000000 1.000000</xyz>
        <limit>
          <lower>-0.005000</lower>
          <upper>0.005000</upper>
        </limit>
        <dynamics>
          <damping>10.000000</damping>
          <friction>0.000000</friction>
        </dynamics>
        <use_parent_model_frame>true</use_parent_model_frame>
      </axis>
    </joint>
    <link name="link_09">

      <pose>0.450000 0.000000 0.000000 0.000000 -0.000000 0.000000</pose>
      <inertial>
        <pose>0.000000 0.000000 0.000000 0.000000 -0.000000 0.000000</pose>
        <mass>0.0100000</mass>
        <inertia>
          <ixx>0.010000</ixx>
          <ixy>0.000000</ixy>
          <ixz>0.000000</ixz>
          <iyy>0.010000</iyy>
          <iyz>0.000000</iyz>
          <izz>0.010000</izz>
        </inertia>
      </inertial>
      <collision name="link_09_collision">
        <pose>0.025000 0.000000 0.000000 0.000000 1.570790 0.000000</pose>
        <geometry>
          <cylinder>
            <length>0.050000</length>
            <radius>0.007500</radius>
          </cylinder>
        </geometry>
      </collision>
      <visual name="link_09_vis">
        <pose>0.025000 0.000000 0.000000 0.000000 1.570790 0.000000</pose>
        <geometry>
          <cylinder>
            <length>0.050000</length>
            <radius>0.007500</radius>
          </cylinder>
        </geometry>
      </visual>
      <velocity_decay />
    </link>
    <joint name="joint_09_2" type="revolute">
      <child>link_09</child>
      <parent>sphere_09</parent>
      <axis>
        <xyz>0.000000 1.000000 0.000000</xyz>
        <limit>
          <lower>-0.500000</lower>
          <upper>0.500000</upper>
        </limit>
        <dynamics>
          <damping>10.000000</damping>
          <friction>0.000000</friction>
        </dynamics>
        <use_parent_model_frame>true</use_parent_model_frame>
      </axis>
    </joint>
    <link name="sphere_10">
      <gravity>false</gravity>
      <pose>0.500000 0.000000 0.000000 0.000000 -0.000000 0.000000</pose>
      <inertial>
        <pose>0.000000 0.000000 0.000000 0.000000 -0.000000 0.000000</pose>
        <mass>0.100000</mass>
        <inertia>
          <ixx>0.010000</ixx>
          <ixy>0.000000</ixy>
          <ixz>0.000000</ixz>
          <iyy>0.010000</iyy>
          <iyz>0.000000</iyz>
          <izz>0.010000</izz>
        </inertia>
      </inertial>
      <collision name="sphere_10_collision">
        <pose>0.000000 0.000000 0.000000 0.000000 -0.000000 0.000000</pose>
        <geometry>
          <sphere>
            <radius>0.007500</radius>
          </sphere>
        </geometry>
      </collision>
      <visual name="sphere_10_vis">
        <pose>0.000000 0.000000 0.000000 0.000000 -0.000000 0.000000</pose>
        <geometry>
          <sphere>
            <radius>0.007500</radius>
          </sphere>
        </geometry>
      </visual>
      <velocity_decay />
    </link>
    <joint name="joint_10_1" type="revolute">
      <child>sphere_10</child>
      <parent>link_09</parent>
      <axis>
        <xyz>0.000000 0.000000 1.000000</xyz>
        <limit>
          <lower>-0.005000</lower>
          <upper>0.005000</upper>
        </limit>
        <dynamics>
          <damping>10.000000</damping>
          <friction>0.000000</friction>
        </dynamics>
        <use_parent_model_frame>true</use_parent_model_frame>
      </axis>
    </joint>
   
    <link name="link_10">
  
      <pose>0.500000 0.000000 0.000000 0.000000 -0.000000 0.000000</pose>
      <inertial>
        <pose>0.000000 0.000000 0.000000 0.000000 -0.000000 0.000000</pose>
        <mass>0.0100000</mass>
        <inertia>
          <ixx>0.010000</ixx>
          <ixy>0.000000</ixy>
          <ixz>0.000000</ixz>
          <iyy>0.010000</iyy>
          <iyz>0.000000</iyz>
          <izz>0.010000</izz>
        </inertia>
      </inertial>
      <collision name="link_10_collision">
        <pose>0.025000 0.000000 0.000000 0.000000 1.570790 0.000000</pose>
        <geometry>
          <cylinder>
            <length>0.050000</length>
            <radius>0.007500</radius>
          </cylinder>
        </geometry>
      </collision>
      <visual name="link_10_vis">
        <pose>0.025000 0.000000 0.000000 0.000000 1.570790 0.000000</pose>
        <geometry>
          <cylinder>
            <length>0.050000</length>
            <radius>0.007500</radius>
          </cylinder>
        </geometry>
      </visual>
      <velocity_decay />
    </link>
    <joint name="joint_10_2" type="revolute">
      <child>link_10</child>
      <parent>sphere_10</parent>
      <axis>
        <xyz>0.000000 1.000000 0.000000</xyz>
        <limit>
          <lower>-0.500000</lower>
          <upper>0.500000</upper>
        </limit>
        <dynamics>
          <damping>10.000000</damping>
          <friction>0.000000</friction>
        </dynamics>
        <use_parent_model_frame>true</use_parent_model_frame>
      </axis>
    </joint>
    <link name="sphere_11">
      <gravity>false</gravity>
      <pose>0.550000 0.000000 0.000000 0.000000 -0.000000 0.000000</pose>
      <inertial>
        <pose>0.000000 0.000000 0.000000 0.000000 -0.000000 0.000000</pose>
        <mass>0.100000</mass>
        <inertia>
          <ixx>0.010000</ixx>
          <ixy>0.000000</ixy>
          <ixz>0.000000</ixz>
          <iyy>0.010000</iyy>
          <iyz>0.000000</iyz>
          <izz>0.010000</izz>
        </inertia>
      </inertial>
      <collision name="sphere_11_collision">
        <pose>0.000000 0.000000 0.000000 0.000000 -0.000000 0.000000</pose>
        <geometry>
          <sphere>
            <radius>0.007500</radius>
          </sphere>
        </geometry>
      </collision>
      <visual name="sphere_11_vis">
        <pose>0.000000 0.000000 0.000000 0.000000 -0.000000 0.000000</pose>
        <geometry>
          <sphere>
            <radius>0.007500</radius>
          </sphere>
        </geometry>
      </visual>
      <velocity_decay />
    </link>
    <joint name="joint_11_1" type="revolute">
      <child>sphere_11</child>
      <parent>link_10</parent>
      <axis>
        <xyz>0.000000 0.000000 1.000000</xyz>
        <limit>
          <lower>-0.005000</lower>
          <upper>0.005000</upper>
        </limit>
        <dynamics>
          <damping>10.000000</damping>
          <friction>0.000000</friction>
        </dynamics>
        <use_parent_model_frame>true</use_parent_model_frame>
      </axis>
    </joint>

<link name="link_11">

      <pose>0.550000 0.000000 0.000000 0.000000 -0.000000 0.000000</pose>
      <inertial>
        <pose>0.000000 0.000000 0.000000 0.000000 -0.000000 0.000000</pose>
        <mass>0.0100000</mass>
        <inertia>
          <ixx>0.010000</ixx>
          <ixy>0.000000</ixy>
          <ixz>0.000000</ixz>
          <iyy>0.010000</iyy>
          <iyz>0.000000</iyz>
          <izz>0.010000</izz>
        </inertia>
      </inertial>
      <collision name="link_11_collision">
        <pose>0.025000 0.000000 0.000000 0.000000 1.570790 0.000000</pose>
        <geometry>
          <cylinder>
            <length>0.050000</length>
            <radius>0.007500</radius>
          </cylinder>
        </geometry>
      </collision>
      <visual name="link_11_vis">
        <pose>0.025000 0.000000 0.000000 0.000000 1.570790 0.000000</pose>
        <geometry>
          <cylinder>
            <length>0.050000</length>
            <radius>0.007500</radius>
          </cylinder>
        </geometry>
      </visual>
      <velocity_decay />
    </link>
    <joint name="joint_11_2" type="revolute">
      <child>link_11</child>
      <parent>sphere_11</parent>
      <axis>
        <xyz>0.000000 1.000000 0.000000</xyz>
        <limit>
          <lower>-0.500000</lower> 
          <upper>0.500000</upper>
        </limit>
        <dynamics>
          <damping>10.000000</damping>
          <friction>0.000000</friction>
        </dynamics>
        <use_parent_model_frame>true</use_parent_model_frame>
      </axis>
    </joint>
    <link name="sphere_12">
      <gravity>false</gravity>
      <pose>0.600000 0.000000 0.000000 0.000000 -0.000000 0.000000</pose>
      <inertial>
        <pose>0.000000 0.000000 0.000000 0.000000 -0.000000 0.000000</pose>
        <mass>0.100000</mass>
        <inertia>
          <ixx>0.010000</ixx>
          <ixy>0.000000</ixy>
          <ixz>0.000000</ixz>
          <iyy>0.010000</iyy>
          <iyz>0.000000</iyz>
          <izz>0.010000</izz>
        </inertia>
      </inertial>
      <collision name="sphere_12_collision">
        <pose>0.000000 0.000000 0.000000 0.000000 -0.000000 0.000000</pose>
        <geometry>
          <sphere>
            <radius>0.007500</radius>
          </sphere>
        </geometry>
      </collision>
      <visual name="sphere_12_vis">
        <pose>0.000000 0.000000 0.000000 0.000000 -0.000000 0.000000</pose>
        <geometry>
          <sphere>
            <radius>0.007500</radius>
          </sphere>
        </geometry>
      </visual>
      <velocity_decay />
    </link>
    <joint name="joint_12_1" type="revolute">
      <child>sphere_12</child>
      <parent>link_11</parent>
      <axis>
        <xyz>0.000000 0.000000 1.000000</xyz>
        <limit>
          <lower>-0.005000</lower>
          <upper>0.005000</upper>
        </limit>
        <dynamics>
          <damping>10.000000</damping>
          <friction>0.000000</friction>
        </dynamics>
        <use_parent_model_frame>true</use_parent_model_frame>
      </axis>
    </joint>

<link name="link_12">

      <pose>0.600000 0.000000 0.000000 0.000000 -0.000000 0.000000</pose>
      <inertial>
        <pose>0.000000 0.000000 0.000000 0.000000 -0.000000 0.000000</pose>
        <mass>0.0100000</mass>
        <inertia>
          <ixx>0.010000</ixx>
          <ixy>0.000000</ixy>
          <ixz>0.000000</ixz>
          <iyy>0.010000</iyy>
          <iyz>0.000000</iyz>
          <izz>0.010000</izz>
        </inertia>
      </inertial>
      <collision name="link_12_collision">
        <pose>0.025000 0.000000 0.000000 0.000000 1.570790 0.000000</pose>
        <geometry>
          <cylinder>
            <length>0.050000</length>
            <radius>0.007500</radius>
          </cylinder>
        </geometry>
      </collision>
      <visual name="link_12_vis">
        <pose>0.025000 0.000000 0.000000 0.000000 1.570790 0.000000</pose>
        <geometry>
          <cylinder>
            <length>0.050000</length>
            <radius>0.007500</radius>
          </cylinder>
        </geometry>
      </visual>
      <velocity_decay />
    </link>
    <joint name="joint_12_2" type="revolute">
      <child>link_12</child>
      <parent>sphere_12</parent>
      <axis>
        <xyz>0.000000 1.000000 0.000000</xyz>
        <limit>
          <lower>-0.700000</lower>
          <upper>0.700000</upper>
        </limit>
        <dynamics>
          <damping>10.000000</damping>
          <friction>0.000000</friction>
        </dynamics>
        <use_parent_model_frame>true</use_parent_model_frame>
      </axis>
    </joint>
    <link name="sphere_13">
      <gravity>false</gravity>
      <pose>0.650000 0.000000 0.000000 0.000000 -0.000000 0.000000</pose>
      <inertial>
        <pose>0.000000 0.000000 0.000000 0.000000 -0.000000 0.000000</pose>
        <mass>0.100000</mass>
        <inertia>
          <ixx>0.010000</ixx>
          <ixy>0.000000</ixy>
          <ixz>0.000000</ixz>
          <iyy>0.010000</iyy>
          <iyz>0.000000</iyz>
          <izz>0.010000</izz>
        </inertia>
      </inertial>
      <collision name="sphere_13_collision">
        <pose>0.000000 0.000000 0.000000 0.000000 -0.000000 0.000000</pose>
        <geometry>
          <sphere>
            <radius>0.007500</radius>
          </sphere>
        </geometry>
      </collision>
      <visual name="sphere_13_vis">
        <pose>0.000000 0.000000 0.000000 0.000000 -0.000000 0.000000</pose>
        <geometry>
          <sphere>
            <radius>0.007500</radius>
          </sphere>
        </geometry>
      </visual>
      <velocity_decay />
    </link>
    <joint name="joint_13_1" type="revolute">
      <child>sphere_13</child>
      <parent>link_12</parent>
      <axis>
        <xyz>0.000000 0.000000 1.000000</xyz>
        <limit>
          <lower>-0.700000</lower>
          <upper>0.700000</upper>
        </limit>
        <dynamics>
          <damping>10.000000</damping>
          <friction>0.000000</friction>
        </dynamics>
        <use_parent_model_frame>true</use_parent_model_frame>
      </axis>
    </joint>

<link name="link_13">

      <pose>0.650000 0.000000 0.000000 0.000000 -0.000000 0.000000</pose>
      <inertial>
        <pose>0.000000 0.000000 0.000000 0.000000 -0.000000 0.000000</pose>
        <mass>0.0100000</mass>
        <inertia>
          <ixx>0.010000</ixx>
          <ixy>0.000000</ixy>
          <ixz>0.000000</ixz>
          <iyy>0.010000</iyy>
          <iyz>0.000000</iyz>
          <izz>0.010000</izz>
        </inertia>
      </inertial>
      <collision name="link_13_collision">
        <pose>0.025000 0.000000 0.000000 0.000000 1.570790 0.000000</pose>
        <geometry>
          <cylinder>
            <length>0.050000</length>
            <radius>0.007500</radius>
          </cylinder>
        </geometry>
      </collision>
      <visual name="link_13_vis">
        <pose>0.025000 0.000000 0.000000 0.000000 1.570790 0.000000</pose>
        <geometry>
          <cylinder>
            <length>0.050000</length>
            <radius>0.007500</radius>
          </cylinder>
        </geometry>
      </visual>
      <velocity_decay />
    </link>
    <joint name="joint_13_2" type="revolute">
      <child>link_13</child>
      <parent>sphere_13</parent>
      <axis>
        <xyz>0.000000 1.000000 0.000000</xyz>
        <limit>
          <lower>-0.700000</lower>
          <upper>0.700000</upper>
        </limit>
        <dynamics>
          <damping>10.000000</damping>
          <friction>0.000000</friction>
        </dynamics>
        <use_parent_model_frame>true</use_parent_model_frame>
      </axis>
    </joint>
    <link name="sphere_14">
      <gravity>false</gravity>
      <pose>0.700000 0.000000 0.000000 0.000000 -0.000000 0.000000</pose>
      <inertial>
        <pose>0.000000 0.000000 0.000000 0.000000 -0.000000 0.000000</pose>
        <mass>0.100000</mass>
        <inertia>
          <ixx>0.010000</ixx>
          <ixy>0.000000</ixy>
          <ixz>0.000000</ixz>
          <iyy>0.010000</iyy>
          <iyz>0.000000</iyz>
          <izz>0.010000</izz>
        </inertia>
      </inertial>
      <collision name="sphere_14_collision">
        <pose>0.000000 0.000000 0.000000 0.000000 -0.000000 0.000000</pose>
        <geometry>
          <sphere>
            <radius>0.007500</radius>
          </sphere>
        </geometry>
      </collision>
      <visual name="sphere_14_vis">
        <pose>0.000000 0.000000 0.000000 0.000000 -0.000000 0.000000</pose>
        <geometry>
          <sphere>
            <radius>0.007500</radius>
          </sphere>
        </geometry>
      </visual>
      <velocity_decay />
    </link>
    <joint name="joint_14_1" type="revolute">
      <child>sphere_14</child>
      <parent>link_13</parent>
      <axis>
        <xyz>0.000000 0.000000 1.000000</xyz>
        <limit>
          <lower>-0.700000</lower>
          <upper>0.700000</upper>
        </limit>
        <dynamics>
          <damping>10.000000</damping>
          <friction>0.000000</friction>
        </dynamics>
        <use_parent_model_frame>true</use_parent_model_frame>
      </axis>
    </joint>
    

<link name="link_14">

      <pose>0.700000 0.000000 0.000000 0.000000 -0.000000 0.000000</pose>
      <inertial>
        <pose>0.000000 0.000000 0.000000 0.000000 -0.000000 0.000000</pose>
        <mass>0.0100000</mass>
        <inertia>
          <ixx>0.010000</ixx>
          <ixy>0.000000</ixy>
          <ixz>0.000000</ixz>
          <iyy>0.010000</iyy>
          <iyz>0.000000</iyz>
          <izz>0.010000</izz>
        </inertia>
      </inertial>
      <collision name="link_14_collision">
        <pose>0.025000 0.000000 0.000000 0.000000 1.570790 0.000000</pose>
        <geometry>
          <cylinder>
            <length>0.050000</length>
            <radius>0.007500</radius>
          </cylinder>
        </geometry>
      </collision>
      <visual name="link_14_vis">
        <pose>0.025000 0.000000 0.000000 0.000000 1.570790 0.000000</pose>
        <geometry>
          <cylinder>
            <length>0.050000</length>
            <radius>0.007500</radius>
          </cylinder>
        </geometry>
      </visual>
      <velocity_decay />
    </link>
    <joint name="joint_14_2" type="revolute">
      <child>link_14</child>
      <parent>sphere_14</parent>
      <axis>
        <xyz>0.000000 1.000000 0.000000</xyz>
        <limit>
          <lower>-0.700000</lower>
          <upper>0.700000</upper>
        </limit>
        <dynamics>
          <damping>10.000000</damping>
          <friction>0.000000</friction>
        </dynamics>
        <use_parent_model_frame>true</use_parent_model_frame>
      </axis>
    </joint>
    <link name="sphere_15">
      <gravity>false</gravity>
      <pose>0.750000 0.000000 0.000000 0.000000 -0.000000 0.000000</pose>
      <inertial>
        <pose>0.000000 0.000000 0.000000 0.000000 -0.000000 0.000000</pose>
        <mass>0.100000</mass>
        <inertia>
          <ixx>0.010000</ixx>
          <ixy>0.000000</ixy>
          <ixz>0.000000</ixz>
          <iyy>0.010000</iyy>
          <iyz>0.000000</iyz>
          <izz>0.010000</izz>
        </inertia>
      </inertial>
      <collision name="sphere_15_collision">
        <pose>0.000000 0.000000 0.000000 0.000000 -0.000000 0.000000</pose>
        <geometry>
          <sphere>
            <radius>0.007500</radius>
          </sphere>
        </geometry>
      </collision>
      <visual name="sphere_15_vis">
        <pose>0.000000 0.000000 0.000000 0.000000 -0.000000 0.000000</pose>
        <geometry>
          <sphere>
            <radius>0.007500</radius>
          </sphere>
        </geometry>
      </visual>
      <velocity_decay />
    </link>
    <joint name="joint_15_1" type="revolute">
      <child>sphere_15</child>
      <parent>link_14</parent>
      <axis>
        <xyz>0.000000 0.000000 1.000000</xyz>
        <limit>
          <lower>-0.700000</lower>
          <upper>0.700000</upper>
        </limit>
        <dynamics>
          <damping>10.000000</damping>
          <friction>0.000000</friction>
        </dynamics>
        <use_parent_model_frame>true</use_parent_model_frame>
      </axis>
    </joint>

<link name="link_15">

      <pose>0.750000 0.000000 0.000000 0.000000 -0.000000 0.000000</pose>
      <inertial>
        <pose>0.000000 0.000000 0.000000 0.000000 -0.000000 0.000000</pose>
        <mass>0.0100000</mass>
        <inertia>
          <ixx>0.010000</ixx>
          <ixy>0.000000</ixy>
          <ixz>0.000000</ixz>
          <iyy>0.010000</iyy>
          <iyz>0.000000</iyz>
          <izz>0.010000</izz>
        </inertia>
      </inertial>
      <collision name="link_15_collision">
        <pose>0.025000 0.000000 0.000000 0.000000 1.570790 0.000000</pose>
        <geometry>
          <cylinder>
            <length>0.050000</length>
            <radius>0.007500</radius>
          </cylinder>
        </geometry>
      </collision>
      <visual name="link_15_vis">
        <pose>0.025000 0.000000 0.000000 0.000000 1.570790 0.000000</pose>
        <geometry>
          <cylinder>
            <length>0.050000</length>
            <radius>0.007500</radius>
          </cylinder>
        </geometry>
      </visual>
      <velocity_decay />
    </link>
    <joint name="joint_15_2" type="revolute">
      <child>link_15</child>
      <parent>sphere_15</parent>
      <axis>
        <xyz>0.000000 1.000000 0.000000</xyz>
        <limit>
          <lower>-0.700000</lower>
          <upper>0.700000</upper>
        </limit>
        <dynamics>
          <damping>10.000000</damping>
          <friction>0.000000</friction>
        </dynamics>
        <use_parent_model_frame>true</use_parent_model_frame>
      </axis>
    </joint>
    <link name="sphere_16">
      <gravity>false</gravity>
      <pose>0.800000 0.000000 0.000000 0.000000 -0.000000 0.000000</pose>
      <inertial>
        <pose>0.000000 0.000000 0.000000 0.000000 -0.000000 0.000000</pose>
        <mass>0.100000</mass>
        <inertia>
          <ixx>0.010000</ixx>
          <ixy>0.000000</ixy>
          <ixz>0.000000</ixz>
          <iyy>0.010000</iyy>
          <iyz>0.000000</iyz>
          <izz>0.010000</izz>
        </inertia>
      </inertial>
      <collision name="sphere_16_collision">
        <pose>0.000000 0.000000 0.000000 0.000000 -0.000000 0.000000</pose>
        <geometry>
          <sphere>
            <radius>0.007500</radius>
          </sphere>
        </geometry>
      </collision>
      <visual name="sphere_16_vis">
        <pose>0.000000 0.000000 0.000000 0.000000 -0.000000 0.000000</pose>
        <geometry>
          <sphere>
            <radius>0.007500</radius>
          </sphere>
        </geometry>
      </visual>
      <velocity_decay />
    </link>
    <joint name="joint_16_1" type="revolute">
      <child>sphere_16</child>
      <parent>link_15</parent>
      <axis>
        <xyz>0.000000 0.000000 1.000000</xyz>
        <limit>
          <lower>-0.700000</lower>
          <upper>0.700000</upper>
        </limit>
        <dynamics>
          <damping>10.000000</damping>
          <friction>0.000000</friction>
        </dynamics>
        <use_parent_model_frame>true</use_parent_model_frame>
      </axis>
    </joint>




<!--
<link name="table">
      <pose>0.500000 0.000000 -0.500000 0.000000 1.570790 0.000000</pose>
      <inertial>
        <pose>0.000000 0.000000 0.000000 0.000000 -0.000000 0.000000</pose>
        <mass>100000000</mass>
        <inertia>
          <ixx>10000</ixx>
          <ixy>0.000000</ixy>
          <ixz>0.000000</ixz>
          <iyy>10000</iyy>
          <iyz>0.000000</iyz>
          <izz>10000</izz>
        </inertia>
      </inertial>
      <collision name="wall_collision">
        <pose>0.000000 0.200000 0.000000 0.000000 0.000000 0.000000</pose>
        <geometry>
	  <box>
	    <size> 0.1 1 1 </size>
	  </box>
        </geometry>
      </collision>
      <visual name="wall_vis">
        <pose>0.000000 0.200000 0.000000 0.000000 0.000000 0.000000</pose>
        <geometry>
          <box>
	    <size> 0.1 1 1 </size>
	  </box>
        </geometry>
      </visual>
      <velocity_decay />
    </link>

<joint name="joint_wall" type="fixed">
      <child>table</child>
      <parent>world</parent>
      <axis>
        <use_parent_model_frame>true</use_parent_model_frame>
      </axis>
    </joint>
-->		

  </model>
</sdf>
